<?xml version="1.0" ?>
<!-- =================================================================================== -->
<!-- |    This document was autogenerated by xacro from dummy2-gripperv2.xacro         | -->
<!-- |    EDITING THIS FILE BY HAND IS NOT RECOMMENDED                                 | -->
<!-- =================================================================================== -->
<robot name="dummy2-gripperv2">
  <material name="silver">
    <color rgba="0.700 0.700 0.700 1.000"/>
  </material>
  <transmission name="joint1_tran">
    <type>transmission_interface/SimpleTransmission</type>
    <joint name="joint1">
      <hardwareInterface>hardware_interface/EffortJointInterface</hardwareInterface>
    </joint>
    <actuator name="joint1_actr">
      <hardwareInterface>hardware_interface/EffortJointInterface</hardwareInterface>
      <mechanicalReduction>1</mechanicalReduction>
    </actuator>
  </transmission>
  <transmission name="joint2_tran">
    <type>transmission_interface/SimpleTransmission</type>
    <joint name="joint2">
      <hardwareInterface>hardware_interface/EffortJointInterface</hardwareInterface>
    </joint>
    <actuator name="joint2_actr">
      <hardwareInterface>hardware_interface/EffortJointInterface</hardwareInterface>
      <mechanicalReduction>1</mechanicalReduction>
    </actuator>
  </transmission>
  <transmission name="joint3_tran">
    <type>transmission_interface/SimpleTransmission</type>
    <joint name="joint3">
      <hardwareInterface>hardware_interface/EffortJointInterface</hardwareInterface>
    </joint>
    <actuator name="joint3_actr">
      <hardwareInterface>hardware_interface/EffortJointInterface</hardwareInterface>
      <mechanicalReduction>1</mechanicalReduction>
    </actuator>
  </transmission>
  <transmission name="joint4_tran">
    <type>transmission_interface/SimpleTransmission</type>
    <joint name="joint4">
      <hardwareInterface>hardware_interface/EffortJointInterface</hardwareInterface>
    </joint>
    <actuator name="joint4_actr">
      <hardwareInterface>hardware_interface/EffortJointInterface</hardwareInterface>
      <mechanicalReduction>1</mechanicalReduction>
    </actuator>
  </transmission>
  <transmission name="joint5_tran">
    <type>transmission_interface/SimpleTransmission</type>
    <joint name="joint5">
      <hardwareInterface>hardware_interface/EffortJointInterface</hardwareInterface>
    </joint>
    <actuator name="joint5_actr">
      <hardwareInterface>hardware_interface/EffortJointInterface</hardwareInterface>
      <mechanicalReduction>1</mechanicalReduction>
    </actuator>
  </transmission>
  <transmission name="joint6_tran">
    <type>transmission_interface/SimpleTransmission</type>
    <joint name="joint6">
      <hardwareInterface>hardware_interface/EffortJointInterface</hardwareInterface>
    </joint>
    <actuator name="joint6_actr">
      <hardwareInterface>hardware_interface/EffortJointInterface</hardwareInterface>
      <mechanicalReduction>1</mechanicalReduction>
    </actuator>
  </transmission>
  <transmission name="figer1_tran">
    <type>transmission_interface/SimpleTransmission</type>
    <joint name="figer1">
      <hardwareInterface>hardware_interface/EffortJointInterface</hardwareInterface>
    </joint>
    <actuator name="figer1_actr">
      <hardwareInterface>hardware_interface/EffortJointInterface</hardwareInterface>
      <mechanicalReduction>1</mechanicalReduction>
    </actuator>
  </transmission>
  <transmission name="figer2_tran">
    <type>transmission_interface/SimpleTransmission</type>
    <joint name="figer2">
      <hardwareInterface>hardware_interface/EffortJointInterface</hardwareInterface>
    </joint>
    <actuator name="figer2_actr">
      <hardwareInterface>hardware_interface/EffortJointInterface</hardwareInterface>
      <mechanicalReduction>1</mechanicalReduction>
    </actuator>
  </transmission>
  <transmission name="camera_tran">
    <type>transmission_interface/SimpleTransmission</type>
    <joint name="camera">
      <hardwareInterface>hardware_interface/EffortJointInterface</hardwareInterface>
    </joint>
    <actuator name="camera_actr">
      <hardwareInterface>hardware_interface/EffortJointInterface</hardwareInterface>
      <mechanicalReduction>1</mechanicalReduction>
    </actuator>
  </transmission>
  <transmission name="camera_eye_tran">
    <type>transmission_interface/SimpleTransmission</type>
    <joint name="camera_eye">
      <hardwareInterface>hardware_interface/EffortJointInterface</hardwareInterface>
    </joint>
    <actuator name="camera_eye_actr">
      <hardwareInterface>hardware_interface/EffortJointInterface</hardwareInterface>
      <mechanicalReduction>1</mechanicalReduction>
    </actuator>
  </transmission>
  <gazebo>
    <plugin filename="libgazebo_ros_control.so" name="control"/>
  </gazebo>
  <gazebo reference="base_link">
    <material>Gazebo/Silver</material>
    <mu1>0.2</mu1>
    <mu2>0.2</mu2>
    <self_collide>true</self_collide>
    <gravity>true</gravity>
  </gazebo>
  <gazebo reference="link1_1">
    <material>Gazebo/Silver</material>
    <mu1>0.2</mu1>
    <mu2>0.2</mu2>
    <self_collide>true</self_collide>
  </gazebo>
  <gazebo reference="link2_1">
    <material>Gazebo/Silver</material>
    <mu1>0.2</mu1>
    <mu2>0.2</mu2>
    <self_collide>true</self_collide>
  </gazebo>
  <gazebo reference="link3_1">
    <material>Gazebo/Silver</material>
    <mu1>0.2</mu1>
    <mu2>0.2</mu2>
    <self_collide>true</self_collide>
  </gazebo>
  <gazebo reference="link4_1">
    <material>Gazebo/Silver</material>
    <mu1>0.2</mu1>
    <mu2>0.2</mu2>
    <self_collide>true</self_collide>
  </gazebo>
  <gazebo reference="link5_1">
    <material>Gazebo/Silver</material>
    <mu1>0.2</mu1>
    <mu2>0.2</mu2>
    <self_collide>true</self_collide>
  </gazebo>
  <gazebo reference="link6_1">
    <material>Gazebo/Silver</material>
    <mu1>0.2</mu1>
    <mu2>0.2</mu2>
    <self_collide>true</self_collide>
  </gazebo>
  <gazebo reference="figer1_1">
    <material>Gazebo/Silver</material>
    <mu1>0.2</mu1>
    <mu2>0.2</mu2>
    <self_collide>true</self_collide>
  </gazebo>
  <gazebo reference="figer2_1">
    <material>Gazebo/Silver</material>
    <mu1>0.2</mu1>
    <mu2>0.2</mu2>
    <self_collide>true</self_collide>
  </gazebo>
  <gazebo reference="camera_1">
    <material>Gazebo/Silver</material>
    <mu1>0.2</mu1>
    <mu2>0.2</mu2>
    <self_collide>true</self_collide>
  </gazebo>
  <gazebo reference="camera_eye_1">
    <material>Gazebo/Silver</material>
    <mu1>0.2</mu1>
    <mu2>0.2</mu2>
    <self_collide>true</self_collide>
  </gazebo>
  <link name="base_link">
    <inertial>
      <origin rpy="0 0 0" xyz="2.242591646188575e-07 0.00022711838502637176 0.0543574942352709"/>
      <mass value="1.2152141810431654"/>
      <inertia ixx="0.002105" ixy="-0.0" ixz="0.0" iyy="0.002245" iyz="-1.1e-05" izz="0.002436"/>
    </inertial>
    <visual>
      <origin rpy="0 0 0" xyz="0 0 0"/>
      <geometry>
         <mesh filename="package://dual_arm_control/description/simulation/dummy2/meshes/base_link.stl" scale="0.001 0.001 0.001"/>
      </geometry>
      <material name="silver"/>
    </visual>
    <collision>
      <origin rpy="0 0 0" xyz="0 0 0"/>
      <geometry>
         <mesh filename="package://dual_arm_control/description/simulation/dummy2/meshes/base_link.stl" scale="0.001 0.001 0.001"/>
      </geometry>
    </collision>
  </link>
  <link name="link1_1">
    <inertial>
      <origin rpy="0 0 0" xyz="-0.0056980705903348725 0.00648616835675352 0.012857190819102027"/>
      <mass value="0.1444690972471256"/>
      <inertia ixx="6.5e-05" ixy="2.1e-05" ixz="9e-06" iyy="5.4e-05" iyz="-1.5e-05" izz="9e-05"/>
    </inertial>
    <visual>
      <origin rpy="0 0 0" xyz="0.0 0.0 -0.096"/>
      <geometry>
         <mesh filename="package://dual_arm_control/description/simulation/dummy2/meshes/link1_1.stl" scale="0.001 0.001 0.001"/>
      </geometry>
      <material name="silver"/>
    </visual>
    <collision>
      <origin rpy="0 0 0" xyz="0.0 0.0 -0.096"/>
      <geometry>
         <mesh filename="package://dual_arm_control/description/simulation/dummy2/meshes/link1_1.stl" scale="0.001 0.001 0.001"/>
      </geometry>
    </collision>
  </link>
  <link name="link2_1">
    <inertial>
      <origin rpy="0 0 0" xyz="0.0188447417509659 0.0019829653147296275 0.08367138108787778"/>
      <mass value="0.6521077215074461"/>
      <inertia ixx="0.002179" ixy="-1e-06" ixz="0.000265" iyy="0.002318" iyz="2.2e-05" izz="0.000411"/>
    </inertial>
    <visual>
      <origin rpy="0 0 0" xyz="0.011639 -0.034477 -0.1245"/>
      <geometry>
         <mesh filename="package://dual_arm_control/description/simulation/dummy2/meshes/link2_1.stl" scale="0.001 0.001 0.001"/>
      </geometry>
      <material name="silver"/>
    </visual>
    <collision>
      <origin rpy="0 0 0" xyz="0.011639 -0.034477 -0.1245"/>
      <geometry>
         <mesh filename="package://dual_arm_control/description/simulation/dummy2/meshes/link2_1.stl" scale="0.001 0.001 0.001"/>
      </geometry>
    </collision>
  </link>
  <link name="link3_1">
    <inertial>
      <origin rpy="0 0 0" xyz="-0.01071065579982854 -0.027860026044143744 0.04896369644132431"/>
      <mass value="0.9005346433244714"/>
      <inertia ixx="0.000823" ixy="-4e-05" ixz="8.7e-05" iyy="0.000697" iyz="0.000126" izz="0.000535"/>
    </inertial>
    <visual>
      <origin rpy="0 0 0" xyz="-0.024511 -0.034477 -0.2925"/>
      <geometry>
         <mesh filename="package://dual_arm_control/description/simulation/dummy2/meshes/link3_1.stl" scale="0.001 0.001 0.001"/>
      </geometry>
      <material name="silver"/>
    </visual>
    <collision>
      <origin rpy="0 0 0" xyz="-0.024511 -0.034477 -0.2925"/>
      <geometry>
         <mesh filename="package://dual_arm_control/description/simulation/dummy2/meshes/link3_1.stl" scale="0.001 0.001 0.001"/>
      </geometry>
    </collision>
  </link>
  <link name="link4_1">
    <inertial>
      <origin rpy="0 0 0" xyz="-0.0052376144149527196 0.0600375883820652 0.0005874969147224296"/>
      <mass value="0.3580312221089852"/>
      <inertia ixx="0.000624" ixy="4e-05" ixz="3e-06" iyy="0.000202" iyz="-5e-06" izz="0.000688"/>
    </inertial>
    <visual>
      <origin rpy="0 0 0" xyz="-0.011349 -0.038577 -0.354967"/>
      <geometry>
         <mesh filename="package://dual_arm_control/description/simulation/dummy2/meshes/link4_1.stl" scale="0.001 0.001 0.001"/>
      </geometry>
      <material name="silver"/>
    </visual>
    <collision>
      <origin rpy="0 0 0" xyz="-0.011349 -0.038577 -0.354967"/>
      <geometry>
         <mesh filename="package://dual_arm_control/description/simulation/dummy2/meshes/link4_1.stl" scale="0.001 0.001 0.001"/>
      </geometry>
    </collision>
  </link>
  <link name="link5_1">
    <inertial>
      <origin rpy="0 0 0" xyz="-0.014439500295566867 0.07274346111500346 -0.0007483346369849819"/>
      <mass value="0.7858738652766984"/>
      <inertia ixx="0.00089" ixy="0.000144" ixz="-4e-06" iyy="0.000343" iyz="6e-06" izz="0.000973"/>
    </inertial>
    <visual>
      <origin rpy="0 0 0" xyz="-0.032649 -0.148577 -0.354967"/>
      <geometry>
         <mesh filename="package://dual_arm_control/description/simulation/dummy2/meshes/link5_1.stl" scale="0.001 0.001 0.001"/>
      </geometry>
      <material name="silver"/>
    </visual>
    <collision>
      <origin rpy="0 0 0" xyz="-0.032649 -0.148577 -0.354967"/>
      <geometry>
         <mesh filename="package://dual_arm_control/description/simulation/dummy2/meshes/link5_1.stl" scale="0.001 0.001 0.001"/>
      </geometry>
    </collision>
  </link>
  <link name="link6_1">
    <inertial>
      <origin rpy="0 0 0" xyz="5.087622746753444e-05 0.04245066924408897 6.811081131086194e-05"/>
      <mass value="0.604072405055537"/>
      <inertia ixx="0.000334" ixy="-2e-06" ixz="-1e-06" iyy="0.000382" iyz="2e-06" izz="0.000521"/>
    </inertial>
    <visual>
      <origin rpy="0 0 0" xyz="-0.012827 -0.268077 -0.353741"/>
      <geometry>
         <mesh filename="package://dual_arm_control/description/simulation/dummy2/meshes/link6_1.stl" scale="0.001 0.001 0.001"/>
      </geometry>
      <material name="silver"/>
    </visual>
    <collision>
      <origin rpy="0 0 0" xyz="-0.012827 -0.268077 -0.353741"/>
      <geometry>
         <mesh filename="package://dual_arm_control/description/simulation/dummy2/meshes/link6_1.stl" scale="0.001 0.001 0.001"/>
      </geometry>
    </collision>
  </link>
  <link name="figer1_1">
    <inertial>
      <origin rpy="0 0 0" xyz="-0.001013816286429263 0.017871453686335137 -9.360034337241308e-05"/>
      <mass value="0.0422978780886348"/>
      <inertia ixx="8e-06" ixy="1e-06" ixz="0.0" iyy="2e-06" iyz="0.0" izz="8e-06"/>
    </inertial>
    <visual>
      <origin rpy="0 0 0" xyz="-0.025651 -0.342539 -0.353641"/>
      <geometry>
         <mesh filename="package://dual_arm_control/description/simulation/dummy2/meshes/figer1_1.stl" scale="0.001 0.001 0.001"/>
      </geometry>
      <material name="silver"/>
    </visual>
    <collision>
      <origin rpy="0 0 0" xyz="-0.025651 -0.342539 -0.353641"/>
      <geometry>
         <mesh filename="package://dual_arm_control/description/simulation/dummy2/meshes/figer1_1.stl" scale="0.001 0.001 0.001"/>
      </geometry>
    </collision>
  </link>
  <link name="figer2_1">
    <inertial>
      <origin rpy="0 0 0" xyz="0.001014115315322053 0.01787145295991821 9.418612516776115e-05"/>
      <mass value="0.042297878145578977"/>
      <inertia ixx="8e-06" ixy="-1e-06" ixz="0.0" iyy="2e-06" iyz="-0.0" izz="8e-06"/>
    </inertial>
    <visual>
      <origin rpy="0 0 0" xyz="-0.000651 -0.342539 -0.353741"/>
      <geometry>
         <mesh filename="package://dual_arm_control/description/simulation/dummy2/meshes/figer2_1.stl" scale="0.001 0.001 0.001"/>
      </geometry>
      <material name="silver"/>
    </visual>
    <collision>
      <origin rpy="0 0 0" xyz="-0.000651 -0.342539 -0.353741"/>
      <geometry>
         <mesh filename="package://dual_arm_control/description/simulation/dummy2/meshes/figer2_1.stl" scale="0.001 0.001 0.001"/>
      </geometry>
    </collision>
  </link>
  <link name="camera_1">
    <inertial>
      <origin rpy="0 0 0" xyz="-0.01057327947001216 -0.0033630885053231863 0.07524829561316149"/>
      <mass value="0.21002608042870943"/>
      <inertia ixx="0.000219" ixy="-5e-06" ixz="-6.2e-05" iyy="0.00035" iyz="-7e-06" izz="0.000142"/>
    </inertial>
    <visual>
      <origin rpy="0 0 0" xyz="-0.010961 -0.241477 -0.378629"/>
      <geometry>
         <mesh filename="package://dual_arm_control/description/simulation/dummy2/meshes/camera_1.stl" scale="0.001 0.001 0.001"/>
      </geometry>
      <material name="silver"/>
    </visual>
    <collision>
      <origin rpy="0 0 0" xyz="-0.010961 -0.241477 -0.378629"/>
      <geometry>
         <mesh filename="package://dual_arm_control/description/simulation/dummy2/meshes/camera_1.stl" scale="0.001 0.001 0.001"/>
      </geometry>
    </collision>
  </link>
  <link name="camera_eye_1">
    <inertial>
      <origin rpy="0 0 0" xyz="1.02692821055822e-07 0.0009995702973704668 -4.1596486705097746e-07"/>
      <mass value="0.00124924067072073"/>
      <inertia ixx="0.0" ixy="-0.0" ixz="-0.0" iyy="0.0" iyz="-0.0" izz="0.0"/>
    </inertial>
    <visual>
      <origin rpy="0 0 0" xyz="-0.008323 -0.247156 -0.477458"/>
      <geometry>
         <mesh filename="package://dual_arm_control/description/simulation/dummy2/meshes/camera_eye_1.stl" scale="0.001 0.001 0.001"/>
      </geometry>
      <material name="silver"/>
    </visual>
    <collision>
      <origin rpy="0 0 0" xyz="-0.008323 -0.247156 -0.477458"/>
      <geometry>
         <mesh filename="package://dual_arm_control/description/simulation/dummy2/meshes/camera_eye_1.stl" scale="0.001 0.001 0.001"/>
      </geometry>
    </collision>
  </link>
  <joint name="joint1" type="revolute">
    <origin rpy="0 0 0" xyz="0.0 0.0 0.096"/>
    <parent link="base_link"/>
    <child link="link1_1"/>
    <axis xyz="0.0 -0.0 -1.0"/>
    <limit effort="100" lower="-3.001966" upper="3.001966" velocity="100"/>
  </joint>
  <joint name="joint2" type="revolute">
    <origin rpy="0 0 0" xyz="-0.011639 0.034477 0.0285"/>
    <parent link="link1_1"/>
    <child link="link2_1"/>
    <axis xyz="1.0 0.0 -0.0"/>
    <limit effort="100" lower="-1.570796" upper="1.308997" velocity="100"/>
  </joint>
  <joint name="joint3" type="revolute">
    <origin rpy="0 0 0" xyz="0.03615 0.0 0.168"/>
    <parent link="link2_1"/>
    <child link="link3_1"/>
    <axis xyz="-1.0 -0.0 -0.0"/>
    <limit effort="100" lower="-1.500983" upper="1.570796" velocity="100"/>
  </joint>
  <joint name="joint4" type="revolute">
    <origin rpy="0 0 0" xyz="-0.013162 0.0041 0.062467"/>
    <parent link="link3_1"/>
    <child link="link4_1"/>
    <axis xyz="0.0 -1.0 0.0"/>
    <limit effort="100" lower="-3.141593" upper="3.141593" velocity="100"/>
  </joint>
  <joint name="joint5" type="revolute">
    <origin rpy="0 0 0" xyz="0.0213 0.11 0.0"/>
    <parent link="link4_1"/>
    <child link="link5_1"/>
    <axis xyz="-1.0 -0.0 -0.0"/>
    <limit effort="100" lower="-1.919862" upper="2.094395" velocity="100"/>
  </joint>
  <joint name="joint6" type="revolute">
    <origin rpy="0 0 0" xyz="-0.019822 0.1195 -0.001226"/>
    <parent link="link5_1"/>
    <child link="link6_1"/>
    <axis xyz="0.0 -1.0 -0.0"/>
    <limit effort="100" lower="-3.141593" upper="3.141593" velocity="100"/>
  </joint>
  <joint name="figer1" type="prismatic">
    <origin rpy="0 0 0" xyz="0.012824 0.074462 -0.0001"/>
    <parent link="link6_1"/>
    <child link="figer1_1"/>
    <axis xyz="1.0 -0.0 0.0"/>
    <limit effort="100" lower="0.0" upper="0.028" velocity="100"/>
  </joint>
  <joint name="figer2" type="prismatic">
    <origin rpy="0 0 0" xyz="-0.012176 0.074462 0.0"/>
    <parent link="link6_1"/>
    <child link="figer2_1"/>
    <axis xyz="1.0 -0.0 0.0"/>
    <limit effort="100" lower="-0.028" upper="0.0" velocity="100"/>
  </joint>
  <joint name="camera" type="prismatic">
    <origin rpy="0 0 0" xyz="-0.021688 0.0929 0.023662"/>
    <parent link="link5_1"/>
    <child link="camera_1"/>
    <axis xyz="1.0 -0.0 0.0"/>
    <limit effort="100" lower="0.0" upper="0.0" velocity="100"/>
  </joint>
  <joint name="camera_eye" type="prismatic">
    <origin rpy="0 0 0" xyz="-0.002638 0.005679 0.098829"/>
    <parent link="camera_1"/>
    <child link="camera_eye_1"/>
    <axis xyz="1.0 0.0 0.0"/>
    <limit effort="100" lower="0.0" upper="0.0" velocity="100"/>
  </joint>
</robot>
